Traceback (most recent call last):
  File "main.py", line 45, in <module>
    result = process_user_data(user_input)
  File "src/processors/data_processor.py", line 78, in process_user_data
    validated = validate_input(data)
  File "src/validators/input_validator.py", line 23, in validate_input
    check_constraints(data.values)
  File "src/config/settings_78.js", line 128, in process
    Error: unknown error
RuntimeError: Logic error causes unbounded cache growth