{
  "bug_id": "MRR-LOGIC_ERRORS-202508-0678",
  "category": "logic_errors",
  "subcategory": "algorithmic_error",
  "language": "python",
  "description": "Logic bug: algorithmic_error producing incorrect results",
  "complexity": {
    "spatial_distribution": 14,
    "temporal_spread_months": 1,
    "abstraction_layers": 4,
    "obfuscation_level": "medium",
    "cross_module_dependencies": 3,
    "artifact_types": 3
  },
  "code_snippets": {
    "buggy_code": "def buggy_function_algorithmic_error(data):\n    # Bug: algorithmic_error\n    result = []\n    for item in data:\n        # Buggy logic here\n        if item > 0:\n            result.append(item)\n    return result",
    "fixed_code": "def fixed_function_algorithmic_error(data):\n    # Fixed: algorithmic_error\n    result = []\n    for item in data:\n        # Fixed logic here\n        if item >= 0:\n            result.append(item)\n    return result"
  },
  "scattered_context": [
    {
      "file_path": "utils/file_1.py",
      "content": "class CriticalComponent:\n    def process(self, data):\n        # Critical logic related to logic_errors\n        if not self.validate(data):\n            raise ValueError(\"Invalid data\")\n        return self.transform(data)\n    \n    def validate(self, data):\n        # Validation logic\n        return data is not None",
      "relevance": "critical",
      "relationship": "calls",
      "specific_issue": "Related to logic_errors issue",
      "line_numbers": [
        82
      ]
    },
    {
      "file_path": "models/file_2.py",
      "content": "# Helper code for logic_errors\ndef helper(): pass",
      "relevance": "medium",
      "relationship": "calls",
      "specific_issue": "Related to logic_errors issue",
      "line_numbers": [
        77
      ]
    },
    {
      "file_path": "core/file_3.py",
      "content": "# Helper code for logic_errors\ndef helper(): pass",
      "relevance": "medium",
      "relationship": "tests",
      "specific_issue": "Related to logic_errors issue",
      "line_numbers": [
        143,
        123
      ]
    },
    {
      "file_path": "services/file_4.py",
      "content": "# Helper code for logic_errors\ndef helper(): pass",
      "relevance": "low",
      "relationship": "uses",
      "specific_issue": "Related to logic_errors issue",
      "line_numbers": [
        46,
        178,
        126
      ]
    },
    {
      "file_path": "services/file_5.py",
      "content": "# Helper code for logic_errors\ndef helper(): pass",
      "relevance": "medium",
      "relationship": "imports",
      "specific_issue": "Related to logic_errors issue",
      "line_numbers": [
        49,
        135,
        146,
        115
      ]
    },
    {
      "file_path": "core/file_6.py",
      "content": "# Helper code for logic_errors\ndef helper(): pass",
      "relevance": "low",
      "relationship": "imports",
      "specific_issue": "Related to logic_errors issue",
      "line_numbers": [
        172,
        183
      ]
    },
    {
      "file_path": "core/file_7.py",
      "content": "class CriticalComponent:\n    def process(self, data):\n        # Critical logic related to logic_errors\n        if not self.validate(data):\n            raise ValueError(\"Invalid data\")\n        return self.transform(data)\n    \n    def validate(self, data):\n        # Validation logic\n        return data is not None",
      "relevance": "critical",
      "relationship": "tests",
      "specific_issue": "Related to logic_errors issue",
      "line_numbers": [
        13
      ]
    },
    {
      "file_path": "core/file_8.py",
      "content": "def important_function(param):\n    # Important logic for logic_errors\n    result = []\n    for item in param:\n        result.append(process_item(item))\n    return result",
      "relevance": "high",
      "relationship": "uses",
      "specific_issue": "Related to logic_errors issue",
      "line_numbers": [
        45,
        196,
        174
      ]
    },
    {
      "file_path": "models/file_9.py",
      "content": "# Helper code for logic_errors\ndef helper(): pass",
      "relevance": "low",
      "relationship": "imports",
      "specific_issue": "Related to logic_errors issue",
      "line_numbers": [
        116,
        143,
        50,
        42
      ]
    },
    {
      "file_path": "models/file_10.py",
      "content": "class CriticalComponent:\n    def process(self, data):\n        # Critical logic related to logic_errors\n        if not self.validate(data):\n            raise ValueError(\"Invalid data\")\n        return self.transform(data)\n    \n    def validate(self, data):\n        # Validation logic\n        return data is not None",
      "relevance": "critical",
      "relationship": "implements",
      "specific_issue": "Related to logic_errors issue",
      "line_numbers": [
        99,
        91,
        124
      ]
    },
    {
      "file_path": "helpers/file_11.py",
      "content": "def important_function(param):\n    # Important logic for logic_errors\n    result = []\n    for item in param:\n        result.append(process_item(item))\n    return result",
      "relevance": "high",
      "relationship": "extends",
      "specific_issue": "Related to logic_errors issue",
      "line_numbers": [
        139,
        146,
        86,
        29,
        23
      ]
    },
    {
      "file_path": "core/file_12.py",
      "content": "class CriticalComponent:\n    def process(self, data):\n        # Critical logic related to logic_errors\n        if not self.validate(data):\n            raise ValueError(\"Invalid data\")\n        return self.transform(data)\n    \n    def validate(self, data):\n        # Validation logic\n        return data is not None",
      "relevance": "critical",
      "relationship": "imports",
      "specific_issue": "Related to logic_errors issue",
      "line_numbers": [
        187,
        90,
        158,
        49
      ]
    },
    {
      "file_path": "helpers/file_13.py",
      "content": "# Helper code for logic_errors\ndef helper(): pass",
      "relevance": "low",
      "relationship": "tests",
      "specific_issue": "Related to logic_errors issue",
      "line_numbers": [
        159
      ]
    },
    {
      "file_path": "models/file_14.py",
      "content": "# Helper code for logic_errors\ndef helper(): pass",
      "relevance": "low",
      "relationship": "implements",
      "specific_issue": "Related to logic_errors issue",
      "line_numbers": [
        198,
        153
      ]
    }
  ],
  "temporal_info": {
    "bug_introduced": "2025-07-08",
    "temporal_spread_days": 30,
    "refactoring_events": 5,
    "related_commits": [
      {
        "hash": "5fd67fb9",
        "date": "2025-07-26",
        "message": "Refactored module 0",
        "files": [
          "file_0.py",
          "file_1.py",
          "file_2.py",
          "file_3.py",
          "file_4.py"
        ]
      },
      {
        "hash": "94d3bf18",
        "date": "2025-07-27",
        "message": "Refactored module 1",
        "files": [
          "file_0.py",
          "file_1.py",
          "file_2.py"
        ]
      },
      {
        "hash": "b9169d7a",
        "date": "2025-07-16",
        "message": "Refactored module 2",
        "files": [
          "file_0.py",
          "file_1.py"
        ]
      },
      {
        "hash": "d7263f20",
        "date": "2025-07-15",
        "message": "Refactored module 3",
        "files": [
          "file_0.py",
          "file_1.py",
          "file_2.py",
          "file_3.py",
          "file_4.py"
        ]
      },
      {
        "hash": "8416941f",
        "date": "2025-07-24",
        "message": "Refactored module 4",
        "files": [
          "file_0.py"
        ]
      },
      {
        "hash": "edd0a651",
        "date": "2025-07-25",
        "message": "Refactored module 5",
        "files": [
          "file_0.py",
          "file_1.py",
          "file_2.py",
          "file_3.py"
        ]
      }
    ]
  },
  "retrieval_paths": {
    "explicit": [
      {
        "from": "utils/file_1.py",
        "to": "models/file_2.py",
        "type": "calls"
      },
      {
        "from": "models/file_2.py",
        "to": "core/file_3.py",
        "type": "calls"
      },
      {
        "from": "core/file_3.py",
        "to": "services/file_4.py",
        "type": "extends"
      },
      {
        "from": "services/file_4.py",
        "to": "services/file_5.py",
        "type": "imports"
      },
      {
        "from": "services/file_5.py",
        "to": "core/file_6.py",
        "type": "imports"
      }
    ],
    "implicit": [
      {
        "files": [
          "services/file_4.py",
          "core/file_7.py",
          "models/file_9.py"
        ],
        "pattern": "shared_dependency"
      },
      {
        "files": [
          "models/file_9.py",
          "core/file_6.py",
          "core/file_8.py"
        ],
        "pattern": "shared_dependency"
      },
      {
        "files": [
          "core/file_12.py",
          "core/file_8.py",
          "utils/file_1.py"
        ],
        "pattern": "shared_dependency"
      }
    ],
    "compositional": [
      {
        "path": [
          "models/file_2.py",
          "models/file_9.py"
        ],
        "depth": 1
      },
      {
        "path": [
          "services/file_5.py",
          "core/file_6.py",
          "models/file_2.py"
        ],
        "depth": 2
      },
      {
        "path": [
          "core/file_12.py",
          "core/file_7.py",
          "core/file_3.py",
          "models/file_2.py"
        ],
        "depth": 3
      },
      {
        "path": [
          "models/file_14.py",
          "helpers/file_11.py",
          "services/file_4.py",
          "core/file_8.py",
          "services/file_5.py"
        ],
        "depth": 4
      }
    ]
  },
  "obfuscation": {
    "obfuscation_level": "medium",
    "renamed_entities": {
      "function_0": "czfuxqle",
      "function_1": "dcinvube",
      "function_2": "wkkjztzu",
      "function_3": "nwwixtdq"
    },
    "moved_files": 3,
    "refactored_modules": 0
  },
  "ground_truth": {
    "root_cause": "algorithmic_error in main processing logic",
    "fix_type": "logic_correction",
    "must_find_files": [
      "utils/file_1.py",
      "core/file_7.py",
      "core/file_8.py",
      "models/file_10.py",
      "helpers/file_11.py"
    ],
    "should_find_files": [
      "models/file_2.py",
      "core/file_3.py",
      "services/file_5.py"
    ],
    "expected_behavior": {
      "should_not_error": true,
      "expected_output": "Correct processing result",
      "performance_threshold": 0.6121168257670302
    }
  },
  "test_artifacts": [
    {
      "file_name": "test_logic_errors_1.python",
      "test_code": "import unittest\n\nclass TestLogic_Errors(unittest.TestCase):\n    def test_scenario_1(self):\n        # Test for logic_errors\n        result = function_under_test(test_data)\n        self.assertEqual(result, expected_result)\n",
      "test_type": "e2e"
    },
    {
      "file_name": "test_logic_errors_2.python",
      "test_code": "import unittest\n\nclass TestLogic_Errors(unittest.TestCase):\n    def test_scenario_2(self):\n        # Test for logic_errors\n        result = function_under_test(test_data)\n        self.assertEqual(result, expected_result)\n",
      "test_type": "e2e"
    },
    {
      "file_name": "test_logic_errors_3.python",
      "test_code": "import unittest\n\nclass TestLogic_Errors(unittest.TestCase):\n    def test_scenario_3(self):\n        # Test for logic_errors\n        result = function_under_test(test_data)\n        self.assertEqual(result, expected_result)\n",
      "test_type": "unit"
    }
  ],
  "error_artifacts": [
    {
      "error_type": "logic_errors",
      "error_message": "AssertionError: Expected 5 but got 4",
      "stack_trace": "Traceback (most recent call last):\n  File \"main.py\", line 42, in <module>\n    result = process_data(input_data)\n  File \"processor.py\", line 15, in process_data\n    return transform(validate(data))\n  File \"validator.py\", line 8, in validate\n    raise ValueError(\"Invalid data\")\nValueError: Invalid data",
      "timestamp": "2025-08-07T02:22:49.916464"
    }
  ],
  "symptoms": [
    "Incorrect output produced",
    "Test cases failing",
    "Unexpected behavior"
  ],
  "error_location": {
    "file": "main.py",
    "line": 79,
    "function": "process_function",
    "module": "utils"
  },
  "evaluation_criteria": {
    "must_find_files": [
      "utils/file_1.py",
      "core/file_7.py",
      "models/file_10.py"
    ],
    "should_find_files": [
      "core/file_8.py",
      "helpers/file_11.py"
    ],
    "retrieval_threshold": 0.75,
    "fix_validation": "must_pass_tests"
  }
}