{
  "bug_id": "MRR-LOGIC_ERRORS-202508-0383",
  "category": "logic_errors",
  "subcategory": "infinite_loop",
  "language": "python",
  "description": "Logic bug: infinite_loop producing incorrect results",
  "complexity": {
    "spatial_distribution": 9,
    "temporal_spread_months": 5,
    "abstraction_layers": 2,
    "obfuscation_level": "medium",
    "cross_module_dependencies": 2,
    "artifact_types": 3
  },
  "code_snippets": {
    "buggy_code": "def buggy_function_infinite_loop(data):\n    # Bug: infinite_loop\n    result = []\n    for item in data:\n        # Buggy logic here\n        if item > 0:\n            result.append(item)\n    return result",
    "fixed_code": "def fixed_function_infinite_loop(data):\n    # Fixed: infinite_loop\n    result = []\n    for item in data:\n        # Fixed logic here\n        if item >= 0:\n            result.append(item)\n    return result"
  },
  "scattered_context": [
    {
      "file_path": "helpers/file_1.py",
      "content": "# Helper code for logic_errors\ndef helper(): pass",
      "relevance": "medium",
      "relationship": "extends",
      "specific_issue": "Related to logic_errors issue",
      "line_numbers": [
        194,
        65,
        173,
        136,
        144
      ]
    },
    {
      "file_path": "services/file_2.py",
      "content": "class CriticalComponent:\n    def process(self, data):\n        # Critical logic related to logic_errors\n        if not self.validate(data):\n            raise ValueError(\"Invalid data\")\n        return self.transform(data)\n    \n    def validate(self, data):\n        # Validation logic\n        return data is not None",
      "relevance": "critical",
      "relationship": "uses",
      "specific_issue": "Related to logic_errors issue",
      "line_numbers": [
        193,
        80,
        80
      ]
    },
    {
      "file_path": "helpers/file_3.py",
      "content": "# Helper code for logic_errors\ndef helper(): pass",
      "relevance": "medium",
      "relationship": "extends",
      "specific_issue": "Related to logic_errors issue",
      "line_numbers": [
        10,
        118
      ]
    },
    {
      "file_path": "services/file_4.py",
      "content": "class CriticalComponent:\n    def process(self, data):\n        # Critical logic related to logic_errors\n        if not self.validate(data):\n            raise ValueError(\"Invalid data\")\n        return self.transform(data)\n    \n    def validate(self, data):\n        # Validation logic\n        return data is not None",
      "relevance": "critical",
      "relationship": "imports",
      "specific_issue": "Related to logic_errors issue",
      "line_numbers": [
        48,
        95
      ]
    },
    {
      "file_path": "core/file_5.py",
      "content": "# Helper code for logic_errors\ndef helper(): pass",
      "relevance": "medium",
      "relationship": "uses",
      "specific_issue": "Related to logic_errors issue",
      "line_numbers": [
        119
      ]
    },
    {
      "file_path": "services/file_6.py",
      "content": "# Helper code for logic_errors\ndef helper(): pass",
      "relevance": "low",
      "relationship": "calls",
      "specific_issue": "Related to logic_errors issue",
      "line_numbers": [
        163,
        89,
        56,
        95
      ]
    },
    {
      "file_path": "models/file_7.py",
      "content": "class CriticalComponent:\n    def process(self, data):\n        # Critical logic related to logic_errors\n        if not self.validate(data):\n            raise ValueError(\"Invalid data\")\n        return self.transform(data)\n    \n    def validate(self, data):\n        # Validation logic\n        return data is not None",
      "relevance": "critical",
      "relationship": "calls",
      "specific_issue": "Related to logic_errors issue",
      "line_numbers": [
        137,
        17,
        86,
        184
      ]
    },
    {
      "file_path": "controllers/file_8.py",
      "content": "# Helper code for logic_errors\ndef helper(): pass",
      "relevance": "medium",
      "relationship": "uses",
      "specific_issue": "Related to logic_errors issue",
      "line_numbers": [
        124,
        41
      ]
    },
    {
      "file_path": "helpers/file_9.py",
      "content": "# Helper code for logic_errors\ndef helper(): pass",
      "relevance": "medium",
      "relationship": "extends",
      "specific_issue": "Related to logic_errors issue",
      "line_numbers": [
        24,
        140,
        44,
        91
      ]
    }
  ],
  "temporal_info": {
    "bug_introduced": "2025-03-10",
    "temporal_spread_days": 150,
    "refactoring_events": 1,
    "related_commits": [
      {
        "hash": "5fd67fb9",
        "date": "2025-08-03",
        "message": "Refactored module 0",
        "files": [
          "file_0.py",
          "file_1.py",
          "file_2.py",
          "file_3.py"
        ]
      },
      {
        "hash": "94d3bf18",
        "date": "2025-04-27",
        "message": "Refactored module 1",
        "files": [
          "file_0.py",
          "file_1.py",
          "file_2.py",
          "file_3.py",
          "file_4.py"
        ]
      },
      {
        "hash": "b9169d7a",
        "date": "2025-05-29",
        "message": "Refactored module 2",
        "files": [
          "file_0.py",
          "file_1.py",
          "file_2.py",
          "file_3.py",
          "file_4.py"
        ]
      },
      {
        "hash": "d7263f20",
        "date": "2025-06-15",
        "message": "Refactored module 3",
        "files": [
          "file_0.py",
          "file_1.py",
          "file_2.py",
          "file_3.py",
          "file_4.py"
        ]
      }
    ]
  },
  "retrieval_paths": {
    "explicit": [
      {
        "from": "helpers/file_1.py",
        "to": "services/file_2.py",
        "type": "calls"
      },
      {
        "from": "services/file_2.py",
        "to": "helpers/file_3.py",
        "type": "imports"
      },
      {
        "from": "helpers/file_3.py",
        "to": "services/file_4.py",
        "type": "imports"
      },
      {
        "from": "services/file_4.py",
        "to": "core/file_5.py",
        "type": "imports"
      },
      {
        "from": "core/file_5.py",
        "to": "services/file_6.py",
        "type": "extends"
      }
    ],
    "implicit": [
      {
        "files": [
          "controllers/file_8.py",
          "helpers/file_3.py",
          "services/file_6.py"
        ],
        "pattern": "shared_dependency"
      },
      {
        "files": [
          "controllers/file_8.py",
          "helpers/file_9.py",
          "models/file_7.py"
        ],
        "pattern": "shared_dependency"
      },
      {
        "files": [
          "controllers/file_8.py",
          "services/file_4.py",
          "helpers/file_1.py"
        ],
        "pattern": "shared_dependency"
      }
    ],
    "compositional": [
      {
        "path": [
          "helpers/file_1.py",
          "controllers/file_8.py"
        ],
        "depth": 1
      },
      {
        "path": [
          "models/file_7.py",
          "helpers/file_1.py",
          "services/file_6.py"
        ],
        "depth": 2
      }
    ]
  },
  "obfuscation": {
    "obfuscation_level": "medium",
    "renamed_entities": {
      "function_0": "fwoucdrf",
      "function_1": "ssaorevj",
      "function_2": "tohklvbm",
      "function_3": "fhjoqqib",
      "function_4": "oysvrmyx",
      "function_5": "escyrfvo",
      "function_6": "lelhjusr"
    },
    "moved_files": 4,
    "refactored_modules": 0
  },
  "ground_truth": {
    "root_cause": "infinite_loop in main processing logic",
    "fix_type": "logic_correction",
    "must_find_files": [
      "services/file_2.py",
      "services/file_4.py",
      "models/file_7.py"
    ],
    "should_find_files": [
      "helpers/file_1.py",
      "helpers/file_3.py",
      "core/file_5.py"
    ],
    "expected_behavior": {
      "should_not_error": true,
      "expected_output": "Correct processing result",
      "performance_threshold": 1.4193581434604052
    }
  },
  "test_artifacts": [
    {
      "file_name": "test_logic_errors_1.python",
      "test_code": "import unittest\n\nclass TestLogic_Errors(unittest.TestCase):\n    def test_scenario_1(self):\n        # Test for logic_errors\n        result = function_under_test(test_data)\n        self.assertEqual(result, expected_result)\n",
      "test_type": "e2e"
    }
  ],
  "error_artifacts": [
    {
      "error_type": "logic_errors",
      "error_message": "AssertionError: Expected 5 but got 4",
      "stack_trace": "Traceback (most recent call last):\n  File \"main.py\", line 42, in <module>\n    result = process_data(input_data)\n  File \"processor.py\", line 15, in process_data\n    return transform(validate(data))\n  File \"validator.py\", line 8, in validate\n    raise ValueError(\"Invalid data\")\nValueError: Invalid data",
      "timestamp": "2025-08-07T02:22:49.789268"
    }
  ],
  "symptoms": [
    "Incorrect output produced",
    "Test cases failing",
    "Unexpected behavior"
  ],
  "error_location": {
    "file": "main.py",
    "line": 27,
    "function": "process_function",
    "module": "core"
  },
  "evaluation_criteria": {
    "must_find_files": [
      "services/file_2.py",
      "services/file_4.py",
      "models/file_7.py"
    ],
    "should_find_files": [],
    "retrieval_threshold": 0.75,
    "fix_validation": "must_pass_tests"
  }
}