{
  "bug_id": "MRR-LOGIC_ERRORS-202508-0399",
  "category": "logic_errors",
  "subcategory": "incorrect_calculation",
  "language": "python",
  "description": "Logic bug: incorrect_calculation producing incorrect results",
  "complexity": {
    "spatial_distribution": 9,
    "temporal_spread_months": 2,
    "abstraction_layers": 3,
    "obfuscation_level": "low",
    "cross_module_dependencies": 4,
    "artifact_types": 3
  },
  "code_snippets": {
    "buggy_code": "def buggy_function_incorrect_calculation(data):\n    # Bug: incorrect_calculation\n    result = []\n    for item in data:\n        # Buggy logic here\n        if item > 0:\n            result.append(item)\n    return result",
    "fixed_code": "def fixed_function_incorrect_calculation(data):\n    # Fixed: incorrect_calculation\n    result = []\n    for item in data:\n        # Fixed logic here\n        if item >= 0:\n            result.append(item)\n    return result"
  },
  "scattered_context": [
    {
      "file_path": "core/file_1.py",
      "content": "# Helper code for logic_errors\ndef helper(): pass",
      "relevance": "low",
      "relationship": "imports",
      "specific_issue": "Related to logic_errors issue",
      "line_numbers": [
        44,
        183,
        143,
        117
      ]
    },
    {
      "file_path": "core/file_2.py",
      "content": "# Helper code for logic_errors\ndef helper(): pass",
      "relevance": "low",
      "relationship": "implements",
      "specific_issue": "Related to logic_errors issue",
      "line_numbers": [
        89,
        165,
        51
      ]
    },
    {
      "file_path": "controllers/file_3.py",
      "content": "def important_function(param):\n    # Important logic for logic_errors\n    result = []\n    for item in param:\n        result.append(process_item(item))\n    return result",
      "relevance": "high",
      "relationship": "calls",
      "specific_issue": "Related to logic_errors issue",
      "line_numbers": [
        34,
        152,
        58
      ]
    },
    {
      "file_path": "services/file_4.py",
      "content": "# Helper code for logic_errors\ndef helper(): pass",
      "relevance": "low",
      "relationship": "extends",
      "specific_issue": "Related to logic_errors issue",
      "line_numbers": [
        111
      ]
    },
    {
      "file_path": "utils/file_5.py",
      "content": "# Helper code for logic_errors\ndef helper(): pass",
      "relevance": "low",
      "relationship": "tests",
      "specific_issue": "Related to logic_errors issue",
      "line_numbers": [
        96,
        11
      ]
    },
    {
      "file_path": "core/file_6.py",
      "content": "def important_function(param):\n    # Important logic for logic_errors\n    result = []\n    for item in param:\n        result.append(process_item(item))\n    return result",
      "relevance": "high",
      "relationship": "uses",
      "specific_issue": "Related to logic_errors issue",
      "line_numbers": [
        105,
        198,
        103,
        51
      ]
    },
    {
      "file_path": "helpers/file_7.py",
      "content": "# Helper code for logic_errors\ndef helper(): pass",
      "relevance": "low",
      "relationship": "extends",
      "specific_issue": "Related to logic_errors issue",
      "line_numbers": [
        168
      ]
    },
    {
      "file_path": "utils/file_8.py",
      "content": "class CriticalComponent:\n    def process(self, data):\n        # Critical logic related to logic_errors\n        if not self.validate(data):\n            raise ValueError(\"Invalid data\")\n        return self.transform(data)\n    \n    def validate(self, data):\n        # Validation logic\n        return data is not None",
      "relevance": "critical",
      "relationship": "implements",
      "specific_issue": "Related to logic_errors issue",
      "line_numbers": [
        151
      ]
    },
    {
      "file_path": "utils/file_9.py",
      "content": "# Helper code for logic_errors\ndef helper(): pass",
      "relevance": "medium",
      "relationship": "extends",
      "specific_issue": "Related to logic_errors issue",
      "line_numbers": [
        91
      ]
    }
  ],
  "temporal_info": {
    "bug_introduced": "2025-06-08",
    "temporal_spread_days": 60,
    "refactoring_events": 4,
    "related_commits": [
      {
        "hash": "5fd67fb9",
        "date": "2025-06-12",
        "message": "Refactored module 0",
        "files": [
          "file_0.py",
          "file_1.py",
          "file_2.py",
          "file_3.py",
          "file_4.py"
        ]
      },
      {
        "hash": "94d3bf18",
        "date": "2025-07-21",
        "message": "Refactored module 1",
        "files": [
          "file_0.py",
          "file_1.py"
        ]
      },
      {
        "hash": "b9169d7a",
        "date": "2025-06-09",
        "message": "Refactored module 2",
        "files": [
          "file_0.py",
          "file_1.py"
        ]
      }
    ]
  },
  "retrieval_paths": {
    "explicit": [
      {
        "from": "core/file_1.py",
        "to": "core/file_2.py",
        "type": "calls"
      },
      {
        "from": "core/file_2.py",
        "to": "controllers/file_3.py",
        "type": "extends"
      },
      {
        "from": "controllers/file_3.py",
        "to": "services/file_4.py",
        "type": "imports"
      },
      {
        "from": "services/file_4.py",
        "to": "utils/file_5.py",
        "type": "extends"
      },
      {
        "from": "utils/file_5.py",
        "to": "core/file_6.py",
        "type": "extends"
      }
    ],
    "implicit": [
      {
        "files": [
          "utils/file_9.py",
          "core/file_1.py",
          "helpers/file_7.py"
        ],
        "pattern": "shared_dependency"
      },
      {
        "files": [
          "core/file_6.py",
          "controllers/file_3.py",
          "utils/file_8.py"
        ],
        "pattern": "shared_dependency"
      },
      {
        "files": [
          "services/file_4.py",
          "core/file_6.py",
          "helpers/file_7.py"
        ],
        "pattern": "shared_dependency"
      }
    ],
    "compositional": [
      {
        "path": [
          "utils/file_9.py",
          "services/file_4.py"
        ],
        "depth": 1
      },
      {
        "path": [
          "core/file_6.py",
          "controllers/file_3.py",
          "utils/file_9.py"
        ],
        "depth": 2
      },
      {
        "path": [
          "core/file_6.py",
          "utils/file_8.py",
          "services/file_4.py",
          "controllers/file_3.py"
        ],
        "depth": 3
      }
    ]
  },
  "obfuscation": {
    "obfuscation_level": "low",
    "renamed_entities": {
      "variable_0": "var_0"
    },
    "moved_files": 0,
    "refactored_modules": 0
  },
  "ground_truth": {
    "root_cause": "incorrect_calculation in main processing logic",
    "fix_type": "logic_correction",
    "must_find_files": [
      "controllers/file_3.py",
      "core/file_6.py",
      "utils/file_8.py"
    ],
    "should_find_files": [
      "utils/file_9.py"
    ],
    "expected_behavior": {
      "should_not_error": true,
      "expected_output": "Correct processing result",
      "performance_threshold": 1.1666773819445504
    }
  },
  "test_artifacts": [
    {
      "file_name": "test_logic_errors_1.python",
      "test_code": "import unittest\n\nclass TestLogic_Errors(unittest.TestCase):\n    def test_scenario_1(self):\n        # Test for logic_errors\n        result = function_under_test(test_data)\n        self.assertEqual(result, expected_result)\n",
      "test_type": "integration"
    }
  ],
  "error_artifacts": [
    {
      "error_type": "logic_errors",
      "error_message": "AssertionError: Expected 5 but got 4",
      "stack_trace": "Traceback (most recent call last):\n  File \"main.py\", line 42, in <module>\n    result = process_data(input_data)\n  File \"processor.py\", line 15, in process_data\n    return transform(validate(data))\n  File \"validator.py\", line 8, in validate\n    raise ValueError(\"Invalid data\")\nValueError: Invalid data",
      "timestamp": "2025-08-07T02:22:49.796144"
    }
  ],
  "symptoms": [
    "Incorrect output produced",
    "Test cases failing",
    "Unexpected behavior"
  ],
  "error_location": {
    "file": "main.py",
    "line": 90,
    "function": "process_function",
    "module": "services"
  },
  "evaluation_criteria": {
    "must_find_files": [
      "utils/file_8.py"
    ],
    "should_find_files": [
      "controllers/file_3.py",
      "core/file_6.py"
    ],
    "retrieval_threshold": 0.75,
    "fix_validation": "must_pass_tests"
  }
}