{
  "bug_id": "MRR-SYNTAX_ERRORS-202508-0131",
  "category": "syntax_errors",
  "subcategory": "invalid_character",
  "language": "python",
  "description": "Syntax error: invalid_character causing compilation failure",
  "complexity": {
    "spatial_distribution": 3,
    "temporal_spread_months": 0,
    "abstraction_layers": 1,
    "obfuscation_level": "low",
    "cross_module_dependencies": 0,
    "artifact_types": 3
  },
  "code_snippets": {
    "buggy_code": "def buggy_function_invalid_character(data):\n    # Bug: invalid_character\n    result = []\n    for item in data:\n        # Buggy logic here\n        if item > 0:\n            result.append(item)\n    return result",
    "fixed_code": "def fixed_function_invalid_character(data):\n    # Fixed: invalid_character\n    result = []\n    for item in data:\n        # Fixed logic here\n        if item >= 0:\n            result.append(item)\n    return result"
  },
  "scattered_context": [
    {
      "file_path": "core/file_1.py",
      "content": "# Helper code for syntax_errors\ndef helper(): pass",
      "relevance": "medium",
      "relationship": "imports",
      "specific_issue": "Related to syntax_errors issue",
      "line_numbers": [
        140,
        77,
        108,
        156
      ]
    },
    {
      "file_path": "utils/file_2.py",
      "content": "# Helper code for syntax_errors\ndef helper(): pass",
      "relevance": "low",
      "relationship": "imports",
      "specific_issue": "Related to syntax_errors issue",
      "line_numbers": [
        127
      ]
    },
    {
      "file_path": "core/file_3.py",
      "content": "# Helper code for syntax_errors\ndef helper(): pass",
      "relevance": "low",
      "relationship": "implements",
      "specific_issue": "Related to syntax_errors issue",
      "line_numbers": [
        84
      ]
    }
  ],
  "temporal_info": {
    "bug_introduced": "2025-08-07",
    "temporal_spread_days": 0,
    "refactoring_events": 1,
    "related_commits": [
      {
        "hash": "5fd67fb9",
        "date": "2025-08-07",
        "message": "Refactored module 0",
        "files": [
          "file_0.py"
        ]
      },
      {
        "hash": "94d3bf18",
        "date": "2025-08-07",
        "message": "Refactored module 1",
        "files": [
          "file_0.py"
        ]
      },
      {
        "hash": "b9169d7a",
        "date": "2025-08-07",
        "message": "Refactored module 2",
        "files": [
          "file_0.py",
          "file_1.py"
        ]
      },
      {
        "hash": "d7263f20",
        "date": "2025-08-07",
        "message": "Refactored module 3",
        "files": [
          "file_0.py",
          "file_1.py",
          "file_2.py"
        ]
      }
    ]
  },
  "retrieval_paths": {
    "explicit": [
      {
        "from": "core/file_1.py",
        "to": "utils/file_2.py",
        "type": "imports"
      },
      {
        "from": "utils/file_2.py",
        "to": "core/file_3.py",
        "type": "calls"
      }
    ],
    "implicit": [
      {
        "files": [
          "utils/file_2.py",
          "core/file_3.py",
          "core/file_1.py"
        ],
        "pattern": "shared_dependency"
      }
    ],
    "compositional": [
      {
        "path": [
          "core/file_3.py",
          "utils/file_2.py"
        ],
        "depth": 1
      }
    ]
  },
  "obfuscation": {
    "obfuscation_level": "low",
    "renamed_entities": {
      "variable_0": "var_0"
    },
    "moved_files": 0,
    "refactored_modules": 0
  },
  "ground_truth": {
    "root_cause": "invalid_character in main processing logic",
    "fix_type": "syntax_correction",
    "must_find_files": [],
    "should_find_files": [
      "core/file_1.py"
    ],
    "expected_behavior": {
      "should_not_error": true,
      "expected_output": "Correct processing result",
      "performance_threshold": 1.0039152147414876
    }
  },
  "test_artifacts": [
    {
      "file_name": "test_syntax_errors_1.python",
      "test_code": "import unittest\n\nclass TestSyntax_Errors(unittest.TestCase):\n    def test_scenario_1(self):\n        # Test for syntax_errors\n        result = function_under_test(test_data)\n        self.assertEqual(result, expected_result)\n",
      "test_type": "integration"
    }
  ],
  "error_artifacts": [
    {
      "error_type": "syntax_errors",
      "error_message": "SyntaxError: invalid syntax at line 21",
      "stack_trace": "Traceback (most recent call last):\n  File \"main.py\", line 42, in <module>\n    result = process_data(input_data)\n  File \"processor.py\", line 15, in process_data\n    return transform(validate(data))\n  File \"validator.py\", line 8, in validate\n    raise ValueError(\"Invalid data\")\nValueError: Invalid data",
      "timestamp": "2025-08-07T02:22:49.499890"
    },
    {
      "error_type": "syntax_errors",
      "error_message": "SyntaxError: invalid syntax at line 61",
      "stack_trace": "Traceback (most recent call last):\n  File \"main.py\", line 42, in <module>\n    result = process_data(input_data)\n  File \"processor.py\", line 15, in process_data\n    return transform(validate(data))\n  File \"validator.py\", line 8, in validate\n    raise ValueError(\"Invalid data\")\nValueError: Invalid data",
      "timestamp": "2025-08-07T02:22:49.499891"
    }
  ],
  "symptoms": [
    "Code fails to compile/run",
    "Syntax error message displayed",
    "IDE highlights error"
  ],
  "error_location": {
    "file": "main.py",
    "line": 189,
    "function": "process_function",
    "module": "services"
  },
  "evaluation_criteria": {
    "must_find_files": [],
    "should_find_files": [],
    "retrieval_threshold": 0.75,
    "fix_validation": "must_pass_tests"
  }
}