{
  "bug_id": "MRR-SYNTAX_ERRORS-202508-0423",
  "category": "syntax_errors",
  "subcategory": "missing_semicolon",
  "language": "python",
  "description": "Syntax error: missing_semicolon causing compilation failure",
  "complexity": {
    "spatial_distribution": 3,
    "temporal_spread_months": 3,
    "abstraction_layers": 1,
    "obfuscation_level": "medium",
    "cross_module_dependencies": 1,
    "artifact_types": 3
  },
  "code_snippets": {
    "buggy_code": "def process_data(items):\n    result = []\n    for item in items\n        result.append(item * 2)\n    return result",
    "fixed_code": "def process_data(items):\n    result = []\n    for item in items:\n        result.append(item * 2)\n    return result"
  },
  "scattered_context": [
    {
      "file_path": "controllers/file_1.py",
      "content": "class CriticalComponent:\n    def process(self, data):\n        # Critical logic related to syntax_errors\n        if not self.validate(data):\n            raise ValueError(\"Invalid data\")\n        return self.transform(data)\n    \n    def validate(self, data):\n        # Validation logic\n        return data is not None",
      "relevance": "critical",
      "relationship": "calls",
      "specific_issue": "Related to syntax_errors issue",
      "line_numbers": [
        56,
        194,
        43,
        178,
        92
      ]
    },
    {
      "file_path": "utils/file_2.py",
      "content": "# Helper code for syntax_errors\ndef helper(): pass",
      "relevance": "medium",
      "relationship": "imports",
      "specific_issue": "Related to syntax_errors issue",
      "line_numbers": [
        126,
        113
      ]
    },
    {
      "file_path": "helpers/file_3.py",
      "content": "def important_function(param):\n    # Important logic for syntax_errors\n    result = []\n    for item in param:\n        result.append(process_item(item))\n    return result",
      "relevance": "high",
      "relationship": "imports",
      "specific_issue": "Related to syntax_errors issue",
      "line_numbers": [
        111,
        39,
        84
      ]
    }
  ],
  "temporal_info": {
    "bug_introduced": "2025-05-09",
    "temporal_spread_days": 90,
    "refactoring_events": 4,
    "related_commits": [
      {
        "hash": "5fd67fb9",
        "date": "2025-06-18",
        "message": "Refactored module 0",
        "files": [
          "file_0.py",
          "file_1.py"
        ]
      },
      {
        "hash": "94d3bf18",
        "date": "2025-08-04",
        "message": "Refactored module 1",
        "files": [
          "file_0.py",
          "file_1.py",
          "file_2.py"
        ]
      },
      {
        "hash": "b9169d7a",
        "date": "2025-07-17",
        "message": "Refactored module 2",
        "files": [
          "file_0.py",
          "file_1.py",
          "file_2.py",
          "file_3.py"
        ]
      }
    ]
  },
  "retrieval_paths": {
    "explicit": [
      {
        "from": "controllers/file_1.py",
        "to": "utils/file_2.py",
        "type": "imports"
      },
      {
        "from": "utils/file_2.py",
        "to": "helpers/file_3.py",
        "type": "calls"
      }
    ],
    "implicit": [
      {
        "files": [
          "helpers/file_3.py",
          "controllers/file_1.py",
          "utils/file_2.py"
        ],
        "pattern": "shared_dependency"
      }
    ],
    "compositional": [
      {
        "path": [
          "helpers/file_3.py",
          "controllers/file_1.py"
        ],
        "depth": 1
      }
    ]
  },
  "obfuscation": {
    "obfuscation_level": "medium",
    "renamed_entities": {
      "function_0": "zoigszjg",
      "function_1": "tgswjuzg",
      "function_2": "nhgvfpko",
      "function_3": "vimcnwls"
    },
    "moved_files": 4,
    "refactored_modules": 0
  },
  "ground_truth": {
    "root_cause": "missing_semicolon in main processing logic",
    "fix_type": "syntax_correction",
    "must_find_files": [
      "controllers/file_1.py",
      "helpers/file_3.py"
    ],
    "should_find_files": [
      "utils/file_2.py"
    ],
    "expected_behavior": {
      "should_not_error": true,
      "expected_output": "Correct processing result",
      "performance_threshold": 1.4191606015270988
    }
  },
  "test_artifacts": [
    {
      "file_name": "test_syntax_errors_1.python",
      "test_code": "import unittest\n\nclass TestSyntax_Errors(unittest.TestCase):\n    def test_scenario_1(self):\n        # Test for syntax_errors\n        result = function_under_test(test_data)\n        self.assertEqual(result, expected_result)\n",
      "test_type": "e2e"
    },
    {
      "file_name": "test_syntax_errors_2.python",
      "test_code": "import unittest\n\nclass TestSyntax_Errors(unittest.TestCase):\n    def test_scenario_2(self):\n        # Test for syntax_errors\n        result = function_under_test(test_data)\n        self.assertEqual(result, expected_result)\n",
      "test_type": "unit"
    },
    {
      "file_name": "test_syntax_errors_3.python",
      "test_code": "import unittest\n\nclass TestSyntax_Errors(unittest.TestCase):\n    def test_scenario_3(self):\n        # Test for syntax_errors\n        result = function_under_test(test_data)\n        self.assertEqual(result, expected_result)\n",
      "test_type": "e2e"
    }
  ],
  "error_artifacts": [
    {
      "error_type": "syntax_errors",
      "error_message": "SyntaxError: invalid syntax at line 35",
      "stack_trace": "Traceback (most recent call last):\n  File \"main.py\", line 42, in <module>\n    result = process_data(input_data)\n  File \"processor.py\", line 15, in process_data\n    return transform(validate(data))\n  File \"validator.py\", line 8, in validate\n    raise ValueError(\"Invalid data\")\nValueError: Invalid data",
      "timestamp": "2025-08-07T02:22:49.594207"
    },
    {
      "error_type": "syntax_errors",
      "error_message": "SyntaxError: invalid syntax at line 53",
      "stack_trace": "Traceback (most recent call last):\n  File \"main.py\", line 42, in <module>\n    result = process_data(input_data)\n  File \"processor.py\", line 15, in process_data\n    return transform(validate(data))\n  File \"validator.py\", line 8, in validate\n    raise ValueError(\"Invalid data\")\nValueError: Invalid data",
      "timestamp": "2025-08-07T02:22:49.594209"
    }
  ],
  "symptoms": [
    "Code fails to compile/run",
    "Syntax error message displayed",
    "IDE highlights error"
  ],
  "error_location": {
    "file": "main.py",
    "line": 63,
    "function": "process_function",
    "module": "utils"
  },
  "evaluation_criteria": {
    "must_find_files": [
      "controllers/file_1.py"
    ],
    "should_find_files": [
      "helpers/file_3.py"
    ],
    "retrieval_threshold": 0.75,
    "fix_validation": "must_pass_tests"
  }
}